# pylint: disable-all  # Desativando todos os erros pylint (coloque um comentÃ¡rio explicando o motivo)
from src.models.settings.connection import db_connection_handler
from typing import Dict
from src.models.entities.attendees import Attendees
from src.models.entities.events import Events
from sqlalchemy.exc import IntegrityError,NoResultFound

class AttendeesRepository:
        
    def insert_attendee(self, attendee_info: Dict) -> Dict:
        with db_connection_handler as database:
            try:
                attendee = Attendees(
                    id=attendee_info.get("uuid"),
                    name=attendee_info.get("name"),
                    email=attendee_info.get("email"),
                    event_id=attendee_info.get("event_id"),
                )
                database.session.add(attendee)
                database.session.commit()

                return attendee_info
            
            except IntegrityError:
                raise Exception('Convidado jÃ¡ cadastrado ğŸ™‚ğŸ¥±')
            
            except Exception as exception:
                database.session.rollback()
                raise exception('Houve um erro inesperadoğŸ˜µğŸ¤¯')
            
    def get_attendee_badge_by_id(self, attendee_id: str):
        with db_connection_handler as database:
            try:
                attendee = (
                    database.session
                        .query(Attendees)
                        .join(Events, Events.id == Attendees.event_id)
                        .filter(Attendees.id==attendee_id)
                        .with_entities(
                            Attendees.name,
                            Attendees.email,
                            Events.title
                        )
                        .one()
                )
                return attendee
            
            except NoResultFound:
                raise Exception('Este convidado nÃ£o existe em nosso banco de dados ğŸ¤¨ğŸ¤”')
            
            except Exception as exception:
                database.session.rollback()
                raise exception('Houve um erro inesperadoğŸ˜µğŸ¤¯')
